Workbook
Name Slicer_City: #N/A
Name Slicer_City1: #N/A
Name Slicer_City2: #N/A
Name Slicer_Department: #N/A
Name Slicer_Department1: #N/A
Name Slicer_Department2: #N/A
Name Slicer_Product: #N/A
Name Slicer_Region: #N/A

Sheet Sheet1
G3: Name | H3: Marks
G4: Aman | H4: 85 | I4: =IF(H4>40,"pass","fail") -> pass
G5: Ravi | H5: 72 | I5: =IF(H5>40,"pass","fail") -> pass
G6: Simran | H6: 91 | I6: =IF(H6>40,"pass","fail") -> pass
G7: Karan | H7: 35 | I7: =IF(H7>40,"pass","fail") -> fail
G8: Priya | H8: 78 | I8: =IF(H8>40,"pass","fail") -> pass
F11: Total sum | G11: =SUM(H4:H8) -> 361
F12: Average | G12: =AVERAGE(H4:H8) -> 72.2
F13: count | G13: =COUNT(H4:H8) -> 5
F14: max | G14: =MAX(H4:H8) -> 91
F15: min | G15: =MIN(H4:H8) -> 35
B19: Sales | C19: Target
B20: 10000 | C20: 20000 | D20: =IFERROR(B20/C20,0) -> 0.5
B21: 15000 | C21: 0 | D21: =IFERROR(B21/C21,0) -> 0
B22: 18000 | C22: 30000 | D22: =IFERROR(B22/C22,0) -> 0.6
C26: Employee | D26: Sales | E26: SATATUS
C27: A | D27: 12000 | E27: =IF(D27>=15000,"Good","needs Improvement") -> needs Improvement | I27: (>=) meaning is rather A is equal or greater than B or A is lower than B
C28: B | D28: 15000 | E28: =IF(D28>=15000,"Good","needs Improvement") -> Good | I28: Iferror purpose is to avoding Error in reports
C29: C | D29: 10000 | E29: =IF(D29>=15000,"Good","needs Improvement") -> needs Improvement
C30: D | D30: 18000 | E30: =IF(D30>=15000,"Good","needs Improvement") -> Good
C31: E | D31: 22000 | E31: =IF(D31>=15000,"Good","needs Improvement") -> Good
C34: Total Sales | E34: =SUM(D27:D31) -> 77000
C35: Average Sales | E35: =AVERAGE(D27:D31) -> 15400
C36: Highest Sales | E36: =MAX(D27:D31) -> 22000
C37: Lowest Sales | E37: =MIN(D27:D31) -> 10000
C38: Number of Employees | E38: =COUNT(D27:D31) -> 5
B43: EMP12345 | C43: =LEFT(B43,3) -> EMP | D43: left (b43,3)
C44: =RIGHT(B43,5) -> 12345 | D44: right?(b43,5)
C45: =MID(B43,4,3) -> 123 | D45: mid(b43,4,3)
C46: =LEN(B43) -> 8 | D46: len(b43)
B48: Tajinder Singh | C48: =TRIM(B48) -> Tajinder Singh | D48: trim(b48)
B53: Employee ID
B54: EMP12345 | C54: =LEFT(B54,3) -> EMP | D54: =RIGHT(B54,5) -> 12345 | E54: =LEN(B54) -> 8 | F54: =MID(B54,4,3) -> 123
B55: EMP67890 | C55: =LEFT(B55,3) -> EMP | D55: =RIGHT(B55,5) -> 67890 | E55: =LEN(B55) -> 8 | F55: =MID(B55,4,3) -> 678
B56: EMP54321 | C56: =LEFT(B56,3) -> EMP | D56: =RIGHT(B56,5) -> 54321 | E56: =LEN(B56) -> 8 | F56: =MID(B56,4,3) -> 543
B58: First Name | C58: Last Name
B59: Tajinder | C59: Singh | E59: =_xlfn.CONCAT(B59," ",C59) -> Tajinder Singh
B61: Employee Name
B62: " Tajinder Singh " | C62: =TRIM(B62) -> " Tajinder Singh "
B63: " Ravi Kumar " | C63: =TRIM(B63) -> " Ravi Kumar "
...

Sheet sales Dashboard
B2: Sales Dashboard | V2: Last Updated
V3: =TODAY() -> 46251
B5: Total Sales | G5: Total orders | L5: Average Sales | Q5: Highest sales
B7: =SUM(Sheet1!H456:H465) -> 536000 | G7: =COUNTA(Sheet1!B456:B465) -> 10 | L7: =AVERAGE(Sheet1!H456:H465) -> 53600 | Q7: =MAX(Sheet1!H456:H465) -> 120000

Sheet template
A1: curency code
A2: [$₹-hi-IN]#,##0;[Red][$₹-hi-IN]#,##0

Sheet MIS_Day1.xlsx
A2: Employee ID | B2: Name | C2: Department | D2: Salary | E2: City
A3: EMP001 | B3: Amit | C3: Sales | D3: 35000 | E3: Bengaluru
A4: EMP002 | B4: Neha | C4: HR | D4: 42000 | E4: Delhi
A5: EMP003 | B5: Rahul | C5: IT | D5: 50000 | E5: Pune
A6: EMP004 | B6: Priya | C6: Finance | D6: 47000 | E6: Hyderabad
A7: EMP005 | B7: Karan | C7: Marketing | D7: 65000 | E7: Mumbai

Sheet Dashboard
V1: Last Updated
B2: Employee Dashboard | V2: =TODAY() -> 46251
B5: Total Employee | G5: Total Salary | L5: Average Salary | Q5: Highest Salary
B7: =COUNTA(Sheet1!C432:C439) -> 8 | G7: =SUM(Sheet1!G432:G439) -> 386000 | L7: =AVERAGE(Sheet1!G432:G439) -> 48250 | Q7: =MAX(Sheet1!G432:G439) -> 75000
